Workbook

Sheet How To Use
A1: HOW TO USE THIS LOGBOOK
A2: PURPOSE | B2: This logbook documents every use of AI tools during your MSc thesis in accordance with RSM academic integrity policy. It must be submitted alongside your final thesis.
A3: WHEN TO LOG | B3: Log every AI interaction at the time of use — not retrospectively. Each session with an AI tool = one row. Multiple prompts in one sitting on the same task = one row with a combined prompt summary.
A4: COLUMN: Prompt Summary | B4: Write what you asked the AI in plain language. You do not need to paste the full prompt. 1–2 sentences capturing the intent is sufficient. Example: 'Asked Claude to rewrite Section 4.7 in a more academic tone based on my draft.'
A5: COLUMN: Output Summary | B5: Describe what the AI produced. Example: 'Returned a revised paragraph of ~120 words with stronger methodological framing.'
A6: COLUMN: How Output Was Used | B6: Select from the dropdown. 'Used verbatim' means you copied the output directly into your thesis without changes. 'Adapted' means you rewrote, merged, or edited the output before use.
A7: COLUMN: Sections Affected | B7: Reference the section of your thesis this output relates to. Example: 'Section 4.7 – Data Collection' or 'Gantt Chart (Figure 2)'.
A8: COLUMN: Output Verified? | B8: All factual claims, citations, and analytical outputs from AI must be independently verified before use. Select the method used. 'N – taken at face value' will trigger a flag on the dashboard.
A9: COLUMN: Integrity Impact (1–3) | B9: 1 = Low (formatting, grammar, minor phrasing). 2 = Medium (structure, ideas, argument flow). 3 = High (substantive content, analysis, literature synthesis). When in doubt, score higher.
A10: DASHBOARD | B10: The Summary Dashboard sheet auto-calculates totals, breakdowns, and integrity flags. Review the orange flag section before submission. Any high-impact unverified outputs should be addressed.
A11: SUBMISSION | B11: Export this workbook as a PDF or submit the .xlsx file alongside your thesis. Confirm submission format with your coach.
A12: Note: this copy has been updated based on thesis-related AI support conversations from late January to 14 June 2026. Review before final submission. | B12: Using AI tools is permitted at RSM subject to full transparency. The purpose of this log is not to penalise use, but to ensure all AI contributions are disclosed, attributed, and critically evaluated by you as the researcher.

Sheet AI Usage Log
A1: AI USAGE LOGBOOK · MSc Supply Chain Management Thesis
A2: Esther Bos · RSM Erasmus University · Thesis Coach: Ehsan
A3: This log documents AI tool usage for the MSc thesis. Entries are phrased as support for rewriting, editing, model/code clean-up, interpretation and feedback; no entry represents outsourced full chapter, full model or full code creation.
A4: # | B4: Date | C4: Thesis Phase | D4: AI Tool Used | E4: Model / Version | F4: Task Category | G4: Prompt Summary (what you asked) | H4: Output Summary (what it produced) | I4: How Output Was Used (verbatim / adapted / rejected) | J4: Sections Affected | K4: Output Verified? (Y/N + method) | L4: Time Spent (mins) | M4: Academic Integrity Impact (1–3) | N4: Notes / Limitations
A5: =ROW()-4 -> 1 | B5: 46051 | C5: Phase 1 – Research Design | D5: ChatGPT (OpenAI) | E5: ChatGPT web interface (model/version not always recorded) | F5: Research Design / Brainstorming | G5: Asked for help narrowing the initial Supply Chain Management thesis topic around promotion planning, replenishment, demand uncertainty and the joint replenishment problem. | H5: Suggested possible angles, clarified where the topic could become too broad, and proposed a more manageable scope for the research problem. | I5: Adapted substantially; used only as input for scoping decisions. | J5: Research question, problem statement, thesis scope | K5: Y – compared with thesis manual, supervisor guidance and feasibility constraints | L5: 25 | M5: 2 – Medium (structure / ideation) | N5: No final research question was copied directly; wording was rewritten independently.
A6: =ROW()-4 -> 2 | B6: 46056 | C6: Phase 1 – Research Design | D6: ChatGPT (OpenAI) | E6: ChatGPT web interface (model/version not always recorded) | F6: Literature Search / Source Use | G6: Asked for suggestions on which literature streams to connect: promotion demand, stochastic programming, joint replenishment, coordinated inventory planning and transport capacity. | H6: Produced a structured overview of relevant literature streams and advised how to position the thesis contribution. | I6: Adapted; used as a checklist for literature review coverage. | J6: Literature review structure | K6: Y – checked against actual academic sources before inclusion | L6: 30 | M6: 2 – Medium (structure / ideation) | N6: AI suggestions were not treated as sources; only verified literature was cited.
A7: =ROW()-4 -> 3 | B7: 46062 | C7: Phase 1 – Research Design | D7: ChatGPT (OpenAI) | E7: ChatGPT web interface (model/version not always recorded) | F7: Writing Assistance / Rewriting | G7: Provided draft research-question wording and asked for alternatives that sounded less overcomplicated and more feasible for a master's thesis. | H7: Suggested several simpler formulations and explained differences in scope and defensibility. | I7: Adapted substantially; final wording was selected and rewritten by the student. | J7: Research question and objective | K7: Y – checked for alignment with methodology and available data | L7: 20 | M7: 2 – Medium (structure / ideation) | N7: Main use was rewriting and scope reduction, not generation of research content.
A8: =ROW()-4 -> 4 | B8: 46068 | C8: Phase 1 – Research Design | D8: ChatGPT (OpenAI) | E8: ChatGPT web interface (model/version not always recorded) | F8: Research Design / Brainstorming | G8: Asked whether the thesis should include hypotheses, sub-questions, or only a main research question. | H8: Explained when sub-questions are useful and suggested possible sub-question structure connected to model development, data inputs, experiments and interpretation. | I8: Adapted; used to decide how to organise the thesis around sub-questions. | J8: Introduction and research design | K8: Y – compared with RSM thesis requirements and coach feedback | L8: 20 | M8: 2 – Medium (structure / ideation) | N8: No hypotheses were added without independent consideration.
A9: =ROW()-4 -> 5 | B9: 46075 | C9: Phase 2 – Model & Data Preparation | D9: ChatGPT (OpenAI) | E9: ChatGPT web interface (model/version not always recorded) | F9: Model Formulation Review | G9: Asked for help explaining the modelling assumptions in a defensible way, especially where the model simplifies promotion depth and demand effects. | H9: Suggested softer phrasing and ways to distinguish model scope from real-world retail complexity. | I9: Adapted substantially; used to refine assumption wording. | J9: Methodology and model assumptions | K9: Y – checked against actual model implementation | L9: 25 | M9: 2 – Medium (structure / ideation) | N9: The model itself was not generated by AI; AI helped with clarification and wording.
A10: =ROW()-4 -> 6 | B10: 46080 | C10: Phase 2 – Model & Data Preparation | D10: ChatGPT (OpenAI) | E10: ChatGPT web interface (model/version not always recorded) | F10: Editing / Proofreading | G10: Asked for feedback on mathematical notation and whether variable/parameter descriptions were understandable. | H10: Pointed out places where notation could be clearer and suggested more consistent terminology. | I10: Adapted; notation changes were manually checked against the model. | J10: Mathematical model notation | K10: Y – cross-checked line by line with the implemented formulation | L10: 30 | M10: 2 – Medium (structure / ideation) | N10: Used as a readability check rather than automatic model writing.
A11: =ROW()-4 -> 7 | B11: 46085 | C11: Phase 2 – Model & Data Preparation | D11: ChatGPT (OpenAI) | E11: ChatGPT web interface (model/version not always recorded) | F11: Data Analysis | G11: Asked for help thinking through how to clean transaction data and transform observed sales into usable demand inputs. | H11: Suggested a stepwise data-preparation workflow, including filtering, aggregation and checks for zero observations. | I11: Adapted; used as a checklist while preparing Python analysis. | J11: Data preparation section | K11: Y – verified by running the data cleaning steps and inspecting outputs | L11: 35 | M11: 2 – Medium (structure / ideation) | N11: AI did not supply final data; all outputs came from the dataset and own Python execution.
A12: 8 | B12: 46088 | C12: Phase 4 – Writing & Discussion | D12: ChatGPT (OpenAI) | E12: ChatGPT web interface (model/version not always recorded) | F12: Writing Assistance / Rewriting | G12: Asked for help on how to rewrite literature review in order to cut down on the amount that I had written after feedback from my thesis coach | H12: Provided suggestions on which parts could be left out and gave rewriting suggestions | I12: Adapted minimally; I used some of the rewrite suggestions in order to cut down on the amount of text | J12: Literature review | K12: Y - verified with what I had originally and checked whether the message was still the same | L12: 45 | M12: 2 – Medium (structure / ideation) | N12: Not merely simple rewriting but also asking where to cut down, therefore scores as 2 instead of 1
A13: =ROW()-4 -> 9 | B13: 10/03/2026 until 15/03/2026 | C13: Phase 2 – Model & Data Preparation | D13: ChatGPT (OpenAI) | E13: ChatGPT web interface (model/version not always recorded) | F13: Code / Formula Assistance | G13: Asked for help working on Python code for aggregating weekly demand, checking promotion periods and preparing model input tables. | H13: Provided debugging suggestions, code-structure ideas and explanations of Python operations. | I13: Adapted and tested; code was edited manually and checked by running it. | J13: Python data analysis scripts and model input preparation | K13: Y – verified by code execution and output inspection | L13: 120 | M13: 3 – High (content / analysis) | N13: Logged as coding support, not as full code generation. I had never used Python before, so I used AI as my manual.
A14: =ROW()-4 -> 10 | B14: 46097 | C14: Phase 2 – Model & Data Preparation | D14: ChatGPT (OpenAI) | E14: ChatGPT web interface (model/version not always recorded) | F14: Writing Assistance / Rewriting | G14: Asked for help phrasing why purchased quantities are used as a proxy for demand and why this creates limitations. | H14: Suggested natural wording to distinguish observed sales from true market demand. | I14: Adapted substantially; used in methodological limitations. | J14: Data limitations and methodology | K14: Y – checked against dataset characteristics | L14: 20 | M14: 1 – Low (formatting / grammar) | N14: Primarily wording assistance.
A15: =ROW()-4 -> 11 | B15: 46103 | C15: Phase 2 – Model & Data Preparation | D15: ChatGPT (OpenAI) | E15: ChatGPT web interface (model/version not always recorded) | F15: Data Analysis | G15: Asked for help interpreting regression outputs used to estimate baseline demand and promotion-related demand changes. | H15: Helped translate statistical output into thesis-style interpretation and warned against overclaiming causality. | I15: Adapted; final interpretation was based on own regression results. | J15: Empirical estimation section | K15: Y – checked against regression tables and robustness checks | L15: 30 | M15: 2 – Medium (structure / ideation) | N15: No unsupported causal claims were adopted.
A16: =ROW()-4 -> 12 | B16: 46109 | C16: Phase 2 – Model & Data Preparation | D16: ChatGPT (OpenAI) | E16: ChatGPT web interface (model/version not always recorded) | F16: Research Design / Brainstorming | G16: Asked whether additional robustness checks or alternative demand periods would be useful within the limited thesis scope. | H16: Suggested possible checks and explained which ones would be most defensible given time and data limitations. | I16: Adapted; used to decide which checks to mention or test. | J16: Robustness checks and scope justification | K16: Y – compared with feasibility and supervisor expectations | L16: 25 | M16: 2 – Medium (structure / ideation) | N16: Helped prioritize tests rather than create results.
A17: =ROW()-4 -> 13 | B17: 46114 | C17: Phase 2 – Model & Data Preparation | D17: ChatGPT (OpenAI) | E17: ChatGPT web interface (model/version not always recorded) | F17: Model Formulation Review | G17: Asked for feedback on whether the model should be described as a joint replenishment problem and where that phrasing should be adjusted. | H17: Highlighted places where the JRP terminology should be softened or more precisely linked to the actual formulation. | I17: Adapted; changed wording where needed. | J17: Model description and literature positioning | K17: Y – checked against model structure and literature terminology | L17: 25 | M17: 2 – Medium (structure / ideation) | N17: Used to avoid overstating the model's theoretical classification.
A18: =ROW()-4 -> 14 | B18: 46119 | C18: Phase 2 – Model & Data Preparation | D18: ChatGPT (OpenAI) | E18: ChatGPT web interface (model/version not always recorded) | F18: Editing / Proofreading | G18: Asked for help making LaTeX-ready explanations of decision variables, constraints and objective function wording. | H18: Suggested clearer text snippets and more consistent sentence structure around the mathematical formulation. | I18: Adapted; inserted only after checking against the equations. | J18: Mathematical model section | K18: Y – cross-checked with equations and notation list | L18: 30 | M18: 1 – Low (formatting / grammar) | N18: Primarily language and formatting support.
A19: =ROW()-4 -> 15 | B19: 46125 | C19: Phase 3 – Computational Experiments | D19: ChatGPT (OpenAI) | E19: ChatGPT web interface (model/version not always recorded) | F19: Model Formulation Review | G19: Asked for help explaining how demand uncertainty is incorporated through scenarios and why only a limited number of periods/products are included. | H19: Suggested wording to make the scope transparent and defensible without overstating external validity. | I19: Adapted substantially. | J19: Experimental design and methodology | K19: Y – checked against implemented scenario set | L19: 25 | M19: 2 – Medium (structure / ideation) | N19: The limited scope was explicitly stated.
A20: =ROW()-4 -> 16 | B20: 46130 | C20: Phase 3 – Computational Experiments | D20: ChatGPT (OpenAI) | E20: ChatGPT web interface (model/version not always recorded) | F20: Code / Formula Assistance | G20: Asked for help cleaning up Python/Gurobi model code and understanding errors in model input handling. | H20: Provided troubleshooting steps and suggestions for cleaner variable naming and output extraction. | I20: Adapted and tested manually. | J20: Python optimisation model and output tables | K20: Y – verified by re-running the model and checking output consistency | L20: 50 | M20: 2 – Medium (structure / ideation) | N20: Logged as model clean-up and debugging support, not full model generation.
A21: =ROW()-4 -> 17 | B21: 46135 | C21: Phase 3 – Computational Experiments | D21: ChatGPT (OpenAI) | E21: ChatGPT web interface (model/version not always recorded) | F21: Results Interpretation | G21: Asked how to describe the base-case model results in a section based on the outputs of the model | H21: Suggested cautious interpretation language and links between promotion timing, replenishment quantities and capacity use. | I21: Adapted; output was merely used as guidance on how to structure the results section. | J21: Results chapter | K21: Y – compared with model output tables | L21: 25 | M21: 2 – Medium (structure / ideation) | N21: No numerical results were invented by AI.
A22: =ROW()-4 -> 18 | B22: 46140 | C22: Phase 3 – Computational Experiments | D22: ChatGPT (OpenAI) | E22: ChatGPT web interface (model/version not always recorded) | F22: Results Interpretation | G22: Asked for help explaining sensitivity results for transport capacity and whether the conclusions were intuitive. | H22: Helped formulate why extra capacity is most valuable when capacity is tight and suggested softer wording for claims. | I22: Adapted substantially. | J22: Sensitivity analysis section | K22: Y – checked against objective values and model output | L22: 25 | M22: 2 – Medium (structure / ideation) | N22: Used for interpretation phrasing only.
A23: =ROW()-4 -> 19 | B23: 46144 | C23: Phase 3 – Computational Experiments | D23: ChatGPT (OpenAI) | E23: ChatGPT web interface (model/version not always recorded) | F23: Results Interpretation | G23: Asked for help interpreting the value of stochastic programming and comparing stochastic versus deterministic model results. | H23: Suggested a concise explanation of VSS and how to describe its relevance in the thesis context. | I23: Adapted; final wording was checked against computed values. | J23: Value of stochastic programming results | K23: Y – verified against calculations and output tables | L23: 30 | M23: 2 – Medium (structure / ideation) | N23: No new calculations were accepted without checking.
A24: =ROW()-4 -> 20 | B24: 46148 | C24: Phase 3 – Computational Experiments | D24: ChatGPT (OpenAI) | E24: ChatGPT web interface (model/version not always recorded) | F24: Results Interpretation | G24: Provided a draft paragraph on promotion budget sensitivity and asked for a clearer, less repetitive interpretation. | H24: Rewrote the paragraph in a more natural academic style while preserving the reported objective values and percentages. | I24: Adapted minimally; numerical values checked manually. | J24: Sensitivity analysis – promotion budget | K24: Y – verified against own results table | L24: 20 | M24: 1 – Low (formatting / grammar) | N24: Main use was rewriting.
A25: =ROW()-4 -> 21 | B25: 46151 | C25: Phase 4 – Writing & Discussion | D25: ChatGPT (OpenAI) | E25: ChatGPT web interface (model/version not always recorded) | F25: Writing Assistance / Rewriting | G25: Asked for help rewriting limitations about promotions not being randomly assigned and the difference between plausible demand patterns and causal effects. | H25: Suggested clearer wording that softened causal claims and linked the limitation to the empirical estimation method. | I25: Adapted substantially. | J25: Limitations and discussion | K25: Y – checked against regression design and data limitations | L25: 20 | M25: 1 – Low (formatting / grammar) | N25: Primarily wording assistance to avoid overstatement.
A26: 22 | B26: 46152 | C26: Phase 4 – Writing & Discussion | D26: ChatGPT (OpenAI) | E26: ChatGPT web interface (model/version not always recorded) | F26: Writing Assistance / Rewriting | G26: Asked for help on Latex tables, gave all of the values that the table should include and asked whether it could create a Latex ready code for these tables | H26: Gave all of the asked Latex tables as output | I26: Used verbatim | J26: Results section and Appendix tables | K26: Y – checked whether the output tables were consistent with my input | L26: 45 | M26: 1 – Low (formatting / grammar) | N26: Formatting of the tables
A27: =ROW()-4 -> 23 | B27: 46156 | C27: Phase 4 – Writing & Discussion | D27: ChatGPT (OpenAI) | E27: ChatGPT web interface (model/version not always recorded) | F27: Writing Assistance / Rewriting | G27: Asked for help rewriting conclusion and limitation paragraphs to avoid repetition from the data limitations section. | H27: Suggested more compact wording and advised distinguishing empirical, modelling and generalisability limitations. | I27: Adapted substantially. | J27: Conclusion and limitations draft | K27: Y – checked for overlap with earlier sections | L27: 25 | M27: 1 – Low (formatting / grammar) | N27: No conclusion chapter was generated in full.
A28: =ROW()-4 -> 24 | B28: 46157 | C28: Phase 4 – Writing & Discussion | D28: ChatGPT (OpenAI) | E28: ChatGPT web interface (model/version not always recorded) | F28: Code / Formula Assistance | G28: Asked for help making a Python file suitable for inclusion in an appendix and resolving LaTeX issues caused by special characters. | H28: Suggested cleaning up code formatting, escaping problematic characters and making code presentation more thesis-ready. | I28: Adapted and checked in Overleaf/LaTeX. | J28: Appendix/code documentation | K28: Y – verified by recompiling the LaTeX document | L28: 30 | M28: 1 – Low (formatting / grammar) | N28: Support focused on presentation and debugging, not writing the full code.
A29: =ROW()-4 -> 25 | B29: 46158 | C29: Phase 4 – Writing & Discussion | D29: ChatGPT (OpenAI) | E29: ChatGPT web interface (model/version not always recorded) | F29: Writing Assistance / Rewriting | G29: Asked how to explain why post-promotion dips were not included, because not all weeks contain observed demand and estimation was not feasible. | H29: Suggested a longer LaTeX-ready paragraph explaining the limitation naturally and defensibly. | I29: Adapted substantially. | J29: Data limitations and discussion | K29: Y – checked against empirical data structure | L29: 20 | M29: 1 – Low (formatting / grammar) | N29: Main use was rewriting and clarification.
A30: =ROW()-4 -> 26 | B30: 46158 | C30: Phase 4 – Writing & Discussion | D30: ChatGPT (OpenAI) | E30: ChatGPT web interface (model/version not always recorded) | F30: Editing / Proofreading | G30: Asked how to make claims in Chapter 5 softer, especially regarding promotion effects and post-promotion demand. | H30: Identified where phrasing sounded too strong and suggested more cautious alternatives. | I30: Adapted; selected phrases were manually inserted. | J30: Results and discussion | K30: Y – checked against empirical limitations | L30: 20 | M30: 1 – Low (formatting / grammar) | N30: Used to reduce overstatement.
A31: =ROW()-4 -> 27 | B31: 46159 | C31: Phase 4 – Writing & Discussion | D31: ChatGPT (OpenAI) | E31: ChatGPT web interface (model/version not always recorded) | F31: Literature Search / Source Use | G31: Asked for help adding references to the discussion using sources already used in the thesis. | H31: Suggested where existing sources could be referenced and provided snippets for connecting discussion points to the literature. | I31: Adapted; references were checked against the thesis bibliography. | J31: Discussion section | K31: Y – verified against sources already included in thesis | L31: 35 | M31: 2 – Medium (structure / ideation) | N31: No new unverified citations were added.
A32: =ROW()-4 -> 28 | B32: 46159 | C32: Final Review | D32: ChatGPT (OpenAI) | E32: ChatGPT web interface (model/version not always recorded) | F32: Editing / Proofreading | G32: Asked for critical feedback on the thesis so far, including inconsistencies, language quality, overstatements and unclear assumptions. | H32: Provided a critical review and pointed out areas where wording should be changed or claims softened. | I32: Adapted; used as a revision checklist. | J32: Whole thesis draft | K32: Y – checked comments manually against the PDF | L32: 45 | M32: 2 – Medium (structure / ideation) | N32: AI comments were selectively used, not accepted automatically.
A33: =ROW()-4 -> 29 | B33: 46159 | C33: Final Review | D33: ChatGPT (OpenAI) | E33: ChatGPT web interface (model/version not always recorded) | F33: Editing / Proofreading | G33: Asked specifically where JRP phrasing should be changed and whether there were additional mistakes. | H33: Pointed to sections where terminology could be misleading and suggested more precise alternatives. | I33: Adapted; terminology adjusted manually. | J33: Model description and discussion | K33: Y – checked against model and literature terminology | L33: 25 | M33: 1 – Low (formatting / grammar) | N33: Narrow proofreading and terminology review.
A34: =ROW()-4 -> 30 | B34: 46162 | C34: Final Review | D34: ChatGPT (OpenAI) | E34: ChatGPT web interface (model/version not always recorded) | F34: Research Design / Brainstorming | G34: Asked whether it was defensible to include only the first five demand periods and whether different demand periods should also be tested. | H34: Explained that the choice can be defensible if clearly justified, but suggested discussing scope and potentially adding a robustness check if feasible. | I34: Adapted; used to prepare justification and supervisor questions. | J34: Scope, robustness checks and limitations | K34: Y – compared with time constraints and available model runs | L34: 20 | M34: 2 – Medium (structure / ideation) | N34: Helped frame a limitation rather than create extra results.
A35: 31 | B35: 46162 | C35: Phase 4 – Writing & Discussion | D35: ChatGPT (OpenAI) | E35: ChatGPT web interface (model/version not always recorded) | F35: Writing Assistance / Rewriting | G35: Asked for sentence-level rewrites to make the managerial relevance and contribution paragraphs less repetitive and less list-like. | H35: Provided sentences that could be changed and which points are important to consider | I35: Adapted; used selected sentences only. | J35: Discussion and managerial implications | K35: Y – proofread in context | L35: 45 | M35: 1 – Low (formatting / grammar) | N35: Main use was rewriting.
A36: 32 | B36: 46163 | C36: Final Review | D36: ChatGPT (OpenAI) | E36: ChatGPT web interface (model/version not always recorded) | F36: Editing / Proofreading | G36: Asked whether the literature review was sufficient and whether the discussion should refer back more explicitly to the literature review. | H36: Suggested strengthening connections between findings and existing literature while avoiding excessive repetition. | I36: Adapted; used as a revision checklist. | J36: Literature review and discussion | K36: Y – checked against actual citations in the thesis | L36: 25 | M36: 2 – Medium (structure / ideation) | N36: Only already-used sources were considered.
A37: 33 | B37: 46164 | C37: Phase 4 – Writing & Discussion | D37: ChatGPT (OpenAI) | E37: ChatGPT web interface (model/version not always recorded) | F37: Writing Assistance / Rewriting | G37: Asked for help rewriting individual sentences to be more natural and academically appropriate. | H37: Provided alternative phrasings for sentences about promotion depth, demand uncertainty, capacity value and model relevance. | I37: Adapted; selected wording was manually inserted. | J37: Results, discussion and limitations | K37: Y – proofread in context | L37: 15 | M37: 1 – Low (formatting / grammar) | N37: Sentence-level rewriting only.
A38: 34 | B38: 46167 | C38: Final Review | D38: ChatGPT (OpenAI) | E38: ChatGPT web interface (model/version not always recorded) | F38: Research Design / Brainstorming | G38: Asked how to improve the thesis, play for Devil's advocate | H38: Suggested priorities such as stronger defence of assumptions, additional robustness justification, clearer answer to the research question and targeted questions. | I38: Adapted; used to prioritise final revisions. | J38: Final revision plan and supervisor meeting preparation | K38: Y – compared with thesis requirements and time remaining | L38: 25 | M38: 2 – Medium (structure / ideation) | N38: Planning support only; no thesis content was copied directly.
A39: 35 | B39: 28/05/2026 | C39: Phase 3 – Computational Experiments | D39: ChatGPT (OpenAI) | E39: ChatGPT web interface (model/version not always recorded) | F39: Code / Formula Assistance | G39: Asked for help cleaning and restructuring the CPLEX code after changing the base model, including clearer variable names, output files and scenario loops. | H39: Provided debugging logic, code-organisation suggestions and checks for consistency between the mathematical formulation and implemented decisions. | I39: Adapted and tested manually; used to make the code easier to read, rerun and document. | J39: Cleaning model code | K39: Y – verified by rerunning model variants and comparing objective values/output tables | L39: 120 | M39: 2 – Medium (structure / ideation) | N39: Making the code easier to read and understand, cleaning and structuring the code.
A40: 36 | B40: 29/05/2026 | C40: Phase 3 – Computational Experiments | D40: ChatGPT (OpenAI) | E40: ChatGPT web interface (model/version not always recorded) | F40: Model Formulation Review | G40: Asked whether emergency trucks should remain in the base model or only be discussed as a possible extension, given that lost sales were cheaper and emergency trucks were not used unless service constraints were imposed. | H40: Explained how to justify excluding emergency trucks from the base model and how to frame them as future research without overcomplicating the thesis. | I40: Adapted; used to clarify model scope and avoid presenting an extension that was not central to the research question. | J40: Methodology, model assumptions and future research | K40: Y – checked against actual model behaviour and sensitivity tests | L40: 35 | M40: 2 – Medium (structure / ideation) | N40: No model feature was added solely on the basis of AI advice.
...

Sheet Summary Dashboard
A1: AI USAGE — SUMMARY DASHBOARD
A2: Summarised from the filled AI Usage Log. Review the entries before submission and adjust any dates/details if needed.
A4: Total Entries | C4: Total Time (mins) | E4: High-Impact Uses (Score 3) | G4: Unverified Outputs
A5: =COUNTA('AI Usage Log'!A5:A70) -> 57 | C5: =SUM('AI Usage Log'!L5:L70) -> 2120 | E5: =COUNTIF('AI Usage Log'!M5:M70,"3 – High (content / analysis)") -> 7 | G5: =COUNTIF('AI Usage Log'!K5:K70,"N*") -> 0
A7: Entries by Thesis Phase | F7: Entries by AI Tool
A8: Phase 1 – Research Design | D8: =COUNTIF('AI Usage Log'!C5:C70,A8) -> 4 | F8: ChatGPT (OpenAI) | H8: =COUNTIF('AI Usage Log'!D5:D70,F8) -> 50
A9: Phase 2 – Model & Data Preparation | D9: =COUNTIF('AI Usage Log'!C5:C70,A9) -> 9 | F9: Claude (Anthropic) | H9: =COUNTIF('AI Usage Log'!D5:D70,F9) -> 4
A10: Phase 3 – Computational Experiments | D10: =COUNTIF('AI Usage Log'!C5:C70,A10) -> 9 | F10: Gemini (Google) | H10: =COUNTIF('AI Usage Log'!D5:D70,F10) -> 1
A11: Phase 4 – Writing & Discussion | D11: =COUNTIF('AI Usage Log'!C5:C70,A11) -> 19 | F11: Copilot (Microsoft) | H11: =COUNTIF('AI Usage Log'!D5:D70,F11) -> 0
A12: Final Review | D12: =COUNTIF('AI Usage Log'!C5:C70,A12) -> 16 | F12: Other | H12: =COUNTIF('AI Usage Log'!D5:D70,F12) -> 0
A15: Entries by Task Category | F15: Integrity Flags
A16: Research Design / Brainstorming | D16: =COUNTIF('AI Usage Log'!F5:F70,A16) -> 5 | F16: High-impact unverified outputs | H16: =COUNTIFS('AI Usage Log'!M5:M70,"3 – High (content / analysis)",'AI Usage Log'!K5:K70,"N*") -> 0
A17: Literature Search / Source Use | D17: =COUNTIF('AI Usage Log'!F5:F70,A17) -> 3 | F17: Verbatim uses (high-impact) | H17: =COUNTIFS('AI Usage Log'!M5:M70,"3 – High (content / analysis)",'AI Usage Log'!I5:I70,"*verbatim*") -> 0
A18: Writing Assistance / Rewriting | D18: =COUNTIF('AI Usage Log'!F5:F70,A18) -> 16 | F18: Entries missing verification | H18: =COUNTIF('AI Usage Log'!K5:K70,"N*") -> 0
A19: Editing / Proofreading | D19: =COUNTIF('AI Usage Log'!F5:F70,A19) -> 9
A20: Model Formulation Review | D20: =COUNTIF('AI Usage Log'!F5:F70,A20) -> 5
A21: Data Analysis | D21: =COUNTIF('AI Usage Log'!F5:F70,A21) -> 2
A22: Code / Formula Assistance | D22: =COUNTIF('AI Usage Log'!F5:F70,A22) -> 5
A23: Results Interpretation | D23: =COUNTIF('AI Usage Log'!F5:F70,A23) -> 5
A24: Final Review / Critical Feedback | D24: =COUNTIF('AI Usage Log'!F5:F70,A24) -> 7
A25: Other | D25: =COUNTIF('AI Usage Log'!F5:F70,A25) -> 0
